package got.common.world.structure.essos.yiti;

import got.common.database.GOTBlocks;
import got.common.database.GOTChestContents;
import got.common.database.GOTItems;
import got.common.entity.animal.GOTEntityHorse;
import got.common.entity.essos.GOTEntityRedPriest;
import got.common.entity.essos.yiti.*;
import got.common.entity.other.inanimate.GOTEntityNPCRespawner;
import net.minecraft.init.Blocks;
import net.minecraft.item.ItemStack;
import net.minecraft.world.World;

import java.util.Random;

public class GOTStructureYiTiFortress extends GOTStructureYiTiBaseTown {
	public GOTStructureYiTiFortress(boolean flag) {
		super(flag);
	}

	@Override
	public boolean generate(World world, Random random, int i, int j, int k, int rotation) {
		int i1;
		int j1;
		int j12;
		int i12;
		int i13;
		int j13;
		int i14;
		int i2;
		int k1;
		int j14;
		int i22;
		int j15;
		int j16;
		int k2;
		int k12;
		int k132;
		int i15;
		int k14;
		setOriginAndRotation(world, i, j, k, rotation, 13);
		setupRandomBlocks(random);
		if (restrictions) {
			int minHeight = 0;
			int maxHeight = 0;
			for (int i16 = -12; i16 <= 12; ++i16) {
				for (k132 = -12; k132 <= 12; ++k132) {
					j13 = getTopBlock(world, i16, k132) - 1;
					if (!isSurface(world, i16, j13, k132)) {
						return false;
					}
					if (j13 < minHeight) {
						minHeight = j13;
					}
					if (j13 > maxHeight) {
						maxHeight = j13;
					}
					if (maxHeight - minHeight <= 12) {
						continue;
					}
					return false;
				}
			}
		}
		for (i14 = -12; i14 <= 12; ++i14) {
			for (k12 = -12; k12 <= 12; ++k12) {
				i22 = Math.abs(i14);
				k2 = Math.abs(k12);
				for (j13 = 1; j13 <= 10; ++j13) {
					setAir(world, i14, j13, k12);
				}
				if (i22 <= 9 && k2 <= 9) {
					for (j13 = 0; (j13 >= 0 || !isOpaque(world, i14, j13, k12)) && getY(j13) >= 0; --j13) {
						setBlockAndMetadata(world, i14, j13, k12, Blocks.dirt, 0);
						setGrassToDirt(world, i14, j13 - 1, k12);
					}
					int randomGround = random.nextInt(3);
					switch (randomGround) {
						case 0:
							setBlockAndMetadata(world, i14, 0, k12, Blocks.grass, 0);
							break;
						case 1:
							setBlockAndMetadata(world, i14, 0, k12, Blocks.dirt, 1);
							break;
						case 2:
							setBlockAndMetadata(world, i14, 0, k12, GOTBlocks.dirtPath, 0);
							break;
					}
					if (random.nextInt(3) == 0) {
						setBlockAndMetadata(world, i14, 1, k12, GOTBlocks.thatchFloor, 0);
					}
				}
				if ((i22 == 12 || i22 == 9) && (k2 == 12 || k2 == 9)) {
					for (j13 = 8; (j13 >= 0 || !isOpaque(world, i14, j13, k12)) && getY(j13) >= 0; --j13) {
						setBlockAndMetadata(world, i14, j13, k12, pillarBlock, pillarMeta);
						setGrassToDirt(world, i14, j13 - 1, k12);
					}
					continue;
				}
				if (i22 == 3 && (k2 == 9 || k2 == 12) || k2 == 3 && (i22 == 9 || i22 == 12)) {
					for (j13 = 7; (j13 >= 0 || !isOpaque(world, i14, j13, k12)) && getY(j13) >= 0; --j13) {
						setBlockAndMetadata(world, i14, j13, k12, pillarBlock, pillarMeta);
						setGrassToDirt(world, i14, j13 - 1, k12);
					}
					if (i22 != 12 && k2 != 12) {
						continue;
					}
					setBlockAndMetadata(world, i14, 8, k12, brickWallBlock, brickWallMeta);
					setBlockAndMetadata(world, i14, 9, k12, Blocks.torch, 5);
					continue;
				}
				if (i22 >= 10 || k2 >= 10) {
					for (j13 = 4; (j13 >= 0 || !isOpaque(world, i14, j13, k12)) && getY(j13) >= 0; --j13) {
						setBlockAndMetadata(world, i14, j13, k12, brickBlock, brickMeta);
						setGrassToDirt(world, i14, j13 - 1, k12);
					}
					setBlockAndMetadata(world, i14, 5, k12, brickGoldBlock, brickGoldMeta);
				}
				if (i22 <= 11 && k2 <= 11 && (i22 >= 10 || k2 >= 10)) {
					setBlockAndMetadata(world, i14, 5, k12, pillarBlock, pillarMeta);
				}
				if (i22 <= 12 && k2 <= 12 && (i22 == 12 || k2 == 12) || i22 <= 9 && k2 <= 9 && (i22 == 9 || k2 == 9)) {
					setBlockAndMetadata(world, i14, 6, k12, brickRedWallBlock, brickRedWallMeta);
				}
				if (i14 == -9 && k2 <= 8) {
					setBlockAndMetadata(world, -9, 5, k12, brickStairBlock, 4);
				}
				if (i14 == 9 && k2 <= 8) {
					setBlockAndMetadata(world, 9, 5, k12, brickStairBlock, 5);
				}
				if (k12 == -9 && i22 <= 8) {
					setBlockAndMetadata(world, i14, 5, -9, brickStairBlock, 7);
				}
				if (k12 != 9 || i22 > 8) {
					continue;
				}
				setBlockAndMetadata(world, i14, 5, k12, brickStairBlock, 6);
			}
		}
		for (i14 = -2; i14 <= 2; ++i14) {
			k12 = -13;
			for (j12 = 0; (j12 >= 0 || !isOpaque(world, i14, j12, k12)) && getY(j12) >= 0; --j12) {
				setBlockAndMetadata(world, i14, j12, k12, pillarBlock, pillarMeta);
				setGrassToDirt(world, i14, j12 - 1, k12);
			}
		}
		for (int i17 : new int[]{-6, 0, 6}) {
			int i23;
			if (i17 != 0) {
				setBlockAndMetadata(world, i17 - 1, 0, -12, pillarBlock, pillarMeta);
				setBlockAndMetadata(world, i17, 0, -12, pillarRedBlock, pillarRedMeta);
				setBlockAndMetadata(world, i17 + 1, 0, -12, pillarBlock, pillarMeta);
				for (i23 = i17 - 1; i23 <= i17 + 1; ++i23) {
					setBlockAndMetadata(world, i23, 1, -12, barsBlock, 0);
					setBlockAndMetadata(world, i23, 2, -12, barsBlock, 0);
				}
				setBlockAndMetadata(world, i17 - 1, 3, -12, brickStairBlock, 4);
				setBlockAndMetadata(world, i17, 3, -12, barsBlock, 0);
				setBlockAndMetadata(world, i17 + 1, 3, -12, brickStairBlock, 5);
				setBlockAndMetadata(world, i17, 4, -12, brickStairBlock, 6);
				setBlockAndMetadata(world, i17, 0, -11, GOTBlocks.hearth, 0);
				setBlockAndMetadata(world, i17, 1, -11, Blocks.fire, 0);
				setBlockAndMetadata(world, i17, 2, -11, brickStairBlock, 6);
			}
			setBlockAndMetadata(world, i17 - 1, 0, 12, pillarBlock, pillarMeta);
			setBlockAndMetadata(world, i17, 0, 12, pillarRedBlock, pillarRedMeta);
			setBlockAndMetadata(world, i17 + 1, 0, 12, pillarBlock, pillarMeta);
			for (i23 = i17 - 1; i23 <= i17 + 1; ++i23) {
				setAir(world, i23, 1, 12);
				setAir(world, i23, 2, 12);
			}
			setBlockAndMetadata(world, i17 - 1, 3, 12, brickStairBlock, 4);
			setAir(world, i17, 3, 12);
			setBlockAndMetadata(world, i17 + 1, 3, 12, brickStairBlock, 5);
			setBlockAndMetadata(world, i17, 4, 12, brickStairBlock, 7);
		}
		int[] i18 = {-6, 0, 6};
		k12 = i18.length;
		for (j12 = 0; j12 < k12; ++j12) {
			int k22;
			k132 = i18[j12];
			setBlockAndMetadata(world, -12, 0, k132 - 1, pillarBlock, pillarMeta);
			setBlockAndMetadata(world, -12, 0, k132, pillarRedBlock, pillarRedMeta);
			setBlockAndMetadata(world, -12, 0, k132 + 1, pillarBlock, pillarMeta);
			for (k22 = k132 - 1; k22 <= k132 + 1; ++k22) {
				setAir(world, -12, 1, k22);
				setAir(world, -12, 2, k22);
			}
			setBlockAndMetadata(world, -12, 3, k132 - 1, brickStairBlock, 7);
			setAir(world, -12, 3, k132);
			setBlockAndMetadata(world, -12, 3, k132 + 1, brickStairBlock, 6);
			setBlockAndMetadata(world, -12, 4, k132, brickStairBlock, 5);
			setBlockAndMetadata(world, 12, 0, k132 - 1, pillarBlock, pillarMeta);
			setBlockAndMetadata(world, 12, 0, k132, pillarRedBlock, pillarRedMeta);
			setBlockAndMetadata(world, 12, 0, k132 + 1, pillarBlock, pillarMeta);
			for (k22 = k132 - 1; k22 <= k132 + 1; ++k22) {
				setAir(world, 12, 1, k22);
				setAir(world, 12, 2, k22);
			}
			setBlockAndMetadata(world, 12, 3, k132 - 1, brickStairBlock, 7);
			setAir(world, 12, 3, k132);
			setBlockAndMetadata(world, 12, 3, k132 + 1, brickStairBlock, 6);
			setBlockAndMetadata(world, 12, 4, k132, brickStairBlock, 4);
		}
		for (i12 = -1; i12 <= 1; ++i12) {
			for (j1 = 1; j1 <= 3; ++j1) {
				setAir(world, i12, j1, -12);
				setBlockAndMetadata(world, i12, j1, -11, gateBlock, 2);
				setAir(world, i12, j1, -10);
			}
		}
		setBlockAndMetadata(world, -1, 4, -12, brickStairBlock, 4);
		setBlockAndMetadata(world, 0, 4, -12, Blocks.torch, 4);
		setBlockAndMetadata(world, 1, 4, -12, brickStairBlock, 5);
		for (i12 = -1; i12 <= 1; ++i12) {
			setBlockAndMetadata(world, i12, 6, -12, brickGoldBlock, brickGoldMeta);
		}
		setBlockAndMetadata(world, -2, 6, -12, brickCarvedBlock, brickCarvedMeta);
		setBlockAndMetadata(world, 2, 6, -12, brickCarvedBlock, brickCarvedMeta);
		setBlockAndMetadata(world, -2, 7, -12, brickStairBlock, 1);
		setBlockAndMetadata(world, -1, 7, -12, brickStairBlock, 0);
		setBlockAndMetadata(world, 0, 7, -12, brickBlock, brickMeta);
		setBlockAndMetadata(world, 0, 8, -12, brickSlabBlock, brickSlabMeta);
		setBlockAndMetadata(world, 1, 7, -12, brickStairBlock, 1);
		setBlockAndMetadata(world, 2, 7, -12, brickStairBlock, 0);
		setBlockAndMetadata(world, -1, 4, -10, brickStairBlock, 4);
		setBlockAndMetadata(world, 0, 4, -10, brickStairBlock, 7);
		setBlockAndMetadata(world, 1, 4, -10, brickStairBlock, 5);
		for (int i17 : new int[]{-3, 3}) {
			placeWallBanner(world, i17, 4, -12, bannerType, 2);
			placeWallBanner(world, i17, 4, 12, bannerType, 0);
		}
		for (int k1321 : new int[]{-3, 3}) {
			placeWallBanner(world, -12, 4, k1321, bannerType, 3);
			placeWallBanner(world, 12, 4, k1321, bannerType, 1);
		}
		placeWallBanner(world, 0, 6, -12, bannerType, 2);
		int[] i19 = {-12, 9};
		j1 = i19.length;
		for (j12 = 0; j12 < j1; ++j12) {
			int i17 = i19[j12];
			for (int k15 : new int[]{-12, 9}) {
				setBlockAndMetadata(world, i17 + 1, 8, k15, brickStairBlock, 0);
				setBlockAndMetadata(world, i17 + 2, 8, k15, brickStairBlock, 1);
				setBlockAndMetadata(world, i17 + 1, 8, k15 + 3, brickStairBlock, 0);
				setBlockAndMetadata(world, i17 + 2, 8, k15 + 3, brickStairBlock, 1);
				setBlockAndMetadata(world, i17, 8, k15 + 1, brickStairBlock, 3);
				setBlockAndMetadata(world, i17, 8, k15 + 2, brickStairBlock, 2);
				setBlockAndMetadata(world, i17 + 3, 8, k15 + 1, brickStairBlock, 3);
				setBlockAndMetadata(world, i17 + 3, 8, k15 + 2, brickStairBlock, 2);
				setBlockAndMetadata(world, i17, 9, k15, brickWallBlock, brickWallMeta);
				setBlockAndMetadata(world, i17 + 3, 9, k15, brickWallBlock, brickWallMeta);
				setBlockAndMetadata(world, i17, 9, k15 + 3, brickWallBlock, brickWallMeta);
				setBlockAndMetadata(world, i17 + 3, 9, k15 + 3, brickWallBlock, brickWallMeta);
				for (i2 = i17 + 1; i2 <= i17 + 2; ++i2) {
					for (int k23 = k15 + 1; k23 <= k15 + 2; ++k23) {
						setBlockAndMetadata(world, i2, 10, k23, roofBlock, roofMeta);
					}
				}
				for (i2 = i17; i2 <= i17 + 3; ++i2) {
					setBlockAndMetadata(world, i2, 10, k15, roofStairBlock, 2);
					setBlockAndMetadata(world, i2, 10, k15 + 3, roofStairBlock, 3);
				}
				for (int k24 = k15 + 1; k24 <= k15 + 2; ++k24) {
					setBlockAndMetadata(world, i17, 10, k24, roofStairBlock, 1);
					setBlockAndMetadata(world, i17 + 3, 10, k24, roofStairBlock, 0);
				}
				if (k15 == -12) {
					setBlockAndMetadata(world, i17 + 1, 6, -12, brickStairBlock, 0);
					setBlockAndMetadata(world, i17 + 2, 6, -12, brickStairBlock, 1);
				}
				if (k15 == 9) {
					setBlockAndMetadata(world, i17 + 1, 6, 9 + 3, brickStairBlock, 0);
					setBlockAndMetadata(world, i17 + 2, 6, 9 + 3, brickStairBlock, 1);
				}
				if (i17 == -12) {
					setBlockAndMetadata(world, -12, 6, k15 + 1, brickStairBlock, 3);
					setBlockAndMetadata(world, -12, 6, k15 + 2, brickStairBlock, 2);
				}
				if (i17 != 9) {
					continue;
				}
				setBlockAndMetadata(world, i17 + 3, 6, k15 + 1, brickStairBlock, 3);
				setBlockAndMetadata(world, i17 + 3, 6, k15 + 2, brickStairBlock, 2);
			}
		}
		setBlockAndMetadata(world, -9, 7, -10, Blocks.torch, 4);
		setBlockAndMetadata(world, -10, 7, -9, Blocks.torch, 1);
		setBlockAndMetadata(world, 9, 7, -10, Blocks.torch, 4);
		setBlockAndMetadata(world, 10, 7, -9, Blocks.torch, 2);
		setBlockAndMetadata(world, -9, 7, 10, Blocks.torch, 3);
		setBlockAndMetadata(world, -10, 7, 9, Blocks.torch, 1);
		setBlockAndMetadata(world, 9, 7, 10, Blocks.torch, 3);
		setBlockAndMetadata(world, 10, 7, 9, Blocks.torch, 2);
		for (i13 = -1; i13 <= 1; ++i13) {
			for (k12 = -12; k12 <= -4; ++k12) {
				if (i13 == 0) {
					setBlockAndMetadata(world, 0, 0, k12, pillarRedBlock, pillarRedMeta);
					continue;
				}
				setBlockAndMetadata(world, i13, 0, k12, pillarBlock, pillarMeta);
			}
		}
		for (k14 = -1; k14 <= 1; ++k14) {
			for (i15 = -9; i15 <= 9; ++i15) {
				if (i15 > -4 && i15 < 4) {
					continue;
				}
				if (k14 == 0) {
					setBlockAndMetadata(world, i15, 0, 0, pillarRedBlock, pillarRedMeta);
					continue;
				}
				setBlockAndMetadata(world, i15, 0, k14, pillarBlock, pillarMeta);
			}
		}
		for (i13 = -3; i13 <= 3; ++i13) {
			for (k12 = -3; k12 <= 3; ++k12) {
				i22 = Math.abs(i13);
				k2 = Math.abs(k12);
				if (i22 == 3 && k2 == 3) {
					for (j13 = 0; j13 <= 5; ++j13) {
						setBlockAndMetadata(world, i13, j13, k12, pillarBlock, pillarMeta);
					}
				} else if (i22 == 3 || k2 == 3) {
					for (j13 = 0; j13 <= 5; ++j13) {
						setBlockAndMetadata(world, i13, j13, k12, brickBlock, brickMeta);
					}
				} else {
					setBlockAndMetadata(world, i13, 0, k12, plankBlock, plankMeta);
				}
				if (i22 > 2 || k2 > 2) {
					continue;
				}
				if (i22 == 2 && k2 == 2) {
					for (j13 = 6; j13 <= 11; ++j13) {
						setBlockAndMetadata(world, i13, j13, k12, pillarBlock, pillarMeta);
					}
					continue;
				}
				if (i22 == 2 || k2 == 2) {
					for (j13 = 6; j13 <= 11; ++j13) {
						if (j13 == 11) {
							setBlockAndMetadata(world, i13, 11, k12, brickGoldBlock, brickGoldMeta);
							continue;
						}
						setBlockAndMetadata(world, i13, j13, k12, brickBlock, brickMeta);
					}
					continue;
				}
				setBlockAndMetadata(world, i13, 6, k12, pillarBlock, pillarMeta);
			}
		}
		for (i13 = -3; i13 <= 3; ++i13) {
			setBlockAndMetadata(world, i13, 6, -3, roofStairBlock, 2);
			setBlockAndMetadata(world, i13, 6, 3, roofStairBlock, 3);
		}
		for (k14 = -2; k14 <= 2; ++k14) {
			setBlockAndMetadata(world, -3, 6, k14, roofStairBlock, 1);
			setBlockAndMetadata(world, 3, 6, k14, roofStairBlock, 0);
		}
		setBlockAndMetadata(world, -4, 6, -4, roofSlabBlock, roofSlabMeta);
		setBlockAndMetadata(world, -3, 5, -4, roofStairBlock, 5);
		setBlockAndMetadata(world, -2, 5, -4, roofStairBlock, 2);
		setBlockAndMetadata(world, -1, 5, -4, roofStairBlock, 4);
		setBlockAndMetadata(world, 0, 6, -4, roofSlabBlock, roofSlabMeta);
		setBlockAndMetadata(world, 1, 5, -4, roofStairBlock, 5);
		setBlockAndMetadata(world, 2, 5, -4, roofStairBlock, 2);
		setBlockAndMetadata(world, 3, 5, -4, roofStairBlock, 4);
		setBlockAndMetadata(world, 4, 6, -4, roofSlabBlock, roofSlabMeta);
		setBlockAndMetadata(world, 4, 5, -3, roofStairBlock, 6);
		setBlockAndMetadata(world, 4, 5, -2, roofStairBlock, 0);
		setBlockAndMetadata(world, 4, 5, -1, roofStairBlock, 7);
		setBlockAndMetadata(world, 4, 6, 0, roofSlabBlock, roofSlabMeta);
		setBlockAndMetadata(world, 4, 5, 1, roofStairBlock, 6);
		setBlockAndMetadata(world, 4, 5, 2, roofStairBlock, 0);
		setBlockAndMetadata(world, 4, 5, 3, roofStairBlock, 7);
		setBlockAndMetadata(world, 4, 6, 4, roofSlabBlock, roofSlabMeta);
		setBlockAndMetadata(world, 3, 5, 4, roofStairBlock, 4);
		setBlockAndMetadata(world, 2, 5, 4, roofStairBlock, 3);
		setBlockAndMetadata(world, 1, 5, 4, roofStairBlock, 5);
		setBlockAndMetadata(world, 0, 6, 4, roofSlabBlock, roofSlabMeta);
		setBlockAndMetadata(world, -1, 5, 4, roofStairBlock, 4);
		setBlockAndMetadata(world, -2, 5, 4, roofStairBlock, 3);
		setBlockAndMetadata(world, -3, 5, 4, roofStairBlock, 5);
		setBlockAndMetadata(world, -4, 6, 4, roofSlabBlock, roofSlabMeta);
		setBlockAndMetadata(world, -4, 5, 3, roofStairBlock, 7);
		setBlockAndMetadata(world, -4, 5, 2, roofStairBlock, 1);
		setBlockAndMetadata(world, -4, 5, 1, roofStairBlock, 6);
		setBlockAndMetadata(world, -4, 6, 0, roofSlabBlock, roofSlabMeta);
		setBlockAndMetadata(world, -4, 5, -1, roofStairBlock, 7);
		setBlockAndMetadata(world, -4, 5, -2, roofStairBlock, 1);
		setBlockAndMetadata(world, -4, 5, -3, roofStairBlock, 6);
		for (i13 = -2; i13 <= 2; ++i13) {
			setBlockAndMetadata(world, i13, 12, -2, roofStairBlock, 2);
			setBlockAndMetadata(world, i13, 12, 2, roofStairBlock, 3);
		}
		for (k14 = -1; k14 <= 1; ++k14) {
			setBlockAndMetadata(world, -2, 12, k14, roofStairBlock, 1);
			setBlockAndMetadata(world, 2, 12, k14, roofStairBlock, 0);
		}
		setBlockAndMetadata(world, -3, 12, -3, roofSlabBlock, roofSlabMeta);
		setBlockAndMetadata(world, -2, 11, -3, roofStairBlock, 5);
		setBlockAndMetadata(world, -1, 11, -3, roofStairBlock, 4);
		setBlockAndMetadata(world, 0, 12, -3, roofSlabBlock, roofSlabMeta);
		setBlockAndMetadata(world, 1, 11, -3, roofStairBlock, 5);
		setBlockAndMetadata(world, 2, 11, -3, roofStairBlock, 4);
		setBlockAndMetadata(world, 3, 12, -3, roofSlabBlock, roofSlabMeta);
		setBlockAndMetadata(world, 3, 11, -2, roofStairBlock, 6);
		setBlockAndMetadata(world, 3, 11, -1, roofStairBlock, 7);
		setBlockAndMetadata(world, 3, 12, 0, roofSlabBlock, roofSlabMeta);
		setBlockAndMetadata(world, 3, 11, 1, roofStairBlock, 6);
		setBlockAndMetadata(world, 3, 11, 2, roofStairBlock, 7);
		setBlockAndMetadata(world, 3, 12, 3, roofSlabBlock, roofSlabMeta);
		setBlockAndMetadata(world, 2, 11, 3, roofStairBlock, 4);
		setBlockAndMetadata(world, 1, 11, 3, roofStairBlock, 5);
		setBlockAndMetadata(world, 0, 12, 3, roofSlabBlock, roofSlabMeta);
		setBlockAndMetadata(world, -1, 11, 3, roofStairBlock, 4);
		setBlockAndMetadata(world, -2, 11, 3, roofStairBlock, 5);
		setBlockAndMetadata(world, -3, 12, 3, roofSlabBlock, roofSlabMeta);
		setBlockAndMetadata(world, -3, 11, 2, roofStairBlock, 7);
		setBlockAndMetadata(world, -3, 11, 1, roofStairBlock, 6);
		setBlockAndMetadata(world, -3, 12, 0, roofSlabBlock, roofSlabMeta);
		setBlockAndMetadata(world, -3, 11, -1, roofStairBlock, 7);
		setBlockAndMetadata(world, -3, 11, -2, roofStairBlock, 6);
		for (i13 = -1; i13 <= 1; ++i13) {
			setBlockAndMetadata(world, i13, 12, -1, roofStairBlock, 7);
			setBlockAndMetadata(world, i13, 12, 1, roofStairBlock, 6);
		}
		setBlockAndMetadata(world, -1, 12, 0, roofStairBlock, 4);
		setBlockAndMetadata(world, 1, 12, 0, roofStairBlock, 5);
		setBlockAndMetadata(world, -1, 13, -1, roofBlock, roofMeta);
		setBlockAndMetadata(world, 0, 13, -1, roofStairBlock, 2);
		setBlockAndMetadata(world, 1, 13, -1, roofBlock, roofMeta);
		setBlockAndMetadata(world, 1, 13, 0, roofStairBlock, 0);
		setBlockAndMetadata(world, 1, 13, 1, roofBlock, roofMeta);
		setBlockAndMetadata(world, 0, 13, 1, roofStairBlock, 3);
		setBlockAndMetadata(world, -1, 13, 1, roofBlock, roofMeta);
		setBlockAndMetadata(world, -1, 13, 0, roofStairBlock, 1);
		setBlockAndMetadata(world, 0, 13, 0, roofBlock, roofMeta);
		setBlockAndMetadata(world, 0, 14, 0, roofBlock, roofMeta);
		setBlockAndMetadata(world, 0, 15, 0, roofWallBlock, roofWallMeta);
		setBlockAndMetadata(world, 0, 16, 0, roofWallBlock, roofWallMeta);
		setBlockAndMetadata(world, -3, 4, -4, Blocks.torch, 4);
		setBlockAndMetadata(world, 3, 4, -4, Blocks.torch, 4);
		setBlockAndMetadata(world, -3, 4, 4, Blocks.torch, 3);
		setBlockAndMetadata(world, 3, 4, 4, Blocks.torch, 3);
		setBlockAndMetadata(world, -4, 4, -3, Blocks.torch, 1);
		setBlockAndMetadata(world, -4, 4, 3, Blocks.torch, 1);
		setBlockAndMetadata(world, 4, 4, -3, Blocks.torch, 2);
		setBlockAndMetadata(world, 4, 4, 3, Blocks.torch, 2);
		setBlockAndMetadata(world, -2, 10, -3, Blocks.torch, 4);
		setBlockAndMetadata(world, 2, 10, -3, Blocks.torch, 4);
		setBlockAndMetadata(world, -2, 10, 3, Blocks.torch, 3);
		setBlockAndMetadata(world, 2, 10, 3, Blocks.torch, 3);
		setBlockAndMetadata(world, -3, 10, -2, Blocks.torch, 1);
		setBlockAndMetadata(world, -3, 10, 2, Blocks.torch, 1);
		setBlockAndMetadata(world, 3, 10, -2, Blocks.torch, 2);
		setBlockAndMetadata(world, 3, 10, 2, Blocks.torch, 2);
		setBlockAndMetadata(world, 0, 1, -3, doorBlock, 1);
		setBlockAndMetadata(world, 0, 2, -3, doorBlock, 8);
		setBlockAndMetadata(world, -3, 1, 0, doorBlock, 2);
		setBlockAndMetadata(world, -3, 2, 0, doorBlock, 8);
		setBlockAndMetadata(world, 3, 1, 0, doorBlock, 0);
		setBlockAndMetadata(world, 3, 2, 0, doorBlock, 8);
		for (k14 = -3; k14 <= 0; ++k14) {
			setBlockAndMetadata(world, 0, 0, k14, pillarRedBlock, pillarRedMeta);
		}
		for (i13 = -3; i13 <= 3; ++i13) {
			setBlockAndMetadata(world, i13, 0, 0, pillarRedBlock, pillarRedMeta);
		}
		for (i13 = -2; i13 <= 2; ++i13) {
			setBlockAndMetadata(world, i13, 5, -2, brickStairBlock, 7);
			setBlockAndMetadata(world, i13, 5, 2, brickStairBlock, 6);
		}
		for (k14 = -2; k14 <= 2; ++k14) {
			setBlockAndMetadata(world, -2, 5, k14, brickStairBlock, 4);
			setBlockAndMetadata(world, 2, 5, k14, brickStairBlock, 5);
		}
		for (j14 = 1; j14 <= 6; ++j14) {
			setBlockAndMetadata(world, 0, j14, 1, pillarBlock, pillarMeta);
			setBlockAndMetadata(world, 0, j14, 0, Blocks.ladder, 2);
			if (j14 > 5) {
				continue;
			}
			setBlockAndMetadata(world, -1, j14, 1, Blocks.ladder, 5);
			setBlockAndMetadata(world, 1, j14, 1, Blocks.ladder, 4);
		}
		for (j14 = 1; j14 <= 5; ++j14) {
			setBlockAndMetadata(world, 0, j14, 2, brickBlock, brickMeta);
		}
		setBlockAndMetadata(world, -2, 2, 2, plankSlabBlock, plankSlabMeta | 8);
		setBlockAndMetadata(world, -1, 2, 2, plankSlabBlock, plankSlabMeta | 8);
		setBlockAndMetadata(world, 1, 2, 2, plankSlabBlock, plankSlabMeta | 8);
		setBlockAndMetadata(world, 2, 2, 2, plankSlabBlock, plankSlabMeta | 8);
		int[] j17 = {1, 3};
		k12 = j17.length;
		for (i22 = 0; i22 < k12; ++i22) {
			j16 = j17[i22];
			setBlockAndMetadata(world, -2, j16, 2, bedBlock, 1);
			setBlockAndMetadata(world, -1, j16, 2, bedBlock, 9);
			setBlockAndMetadata(world, 2, j16, 2, bedBlock, 3);
			setBlockAndMetadata(world, 1, j16, 2, bedBlock, 11);
		}
		setBlockAndMetadata(world, -2, 4, -2, Blocks.torch, 3);
		setBlockAndMetadata(world, 2, 4, -2, Blocks.torch, 3);
		setBlockAndMetadata(world, -2, 4, 2, Blocks.torch, 4);
		setBlockAndMetadata(world, 2, 4, 2, Blocks.torch, 4);
		placeArmorStand(world, -2, 1, -2, 2, null);
		placeArmorStand(world, 2, 1, -2, 2, null);
		placeWeaponRack(world, 0, 3, -2, 4, getWeaponItem(random));
		placeWeaponRack(world, -2, 3, 0, 5, getWeaponItem(random));
		placeWeaponRack(world, 2, 3, 0, 7, getWeaponItem(random));
		for (j15 = 8; j15 <= 9; ++j15) {
			setBlockAndMetadata(world, 0, j15, -2, barsBlock, 0);
			setBlockAndMetadata(world, 0, j15, 2, barsBlock, 0);
			setBlockAndMetadata(world, -2, j15, 0, barsBlock, 0);
			setBlockAndMetadata(world, 2, j15, 0, barsBlock, 0);
		}
		setBlockAndMetadata(world, -1, 11, -1, Blocks.torch, 3);
		setBlockAndMetadata(world, 1, 11, -1, Blocks.torch, 3);
		setBlockAndMetadata(world, -1, 11, 1, Blocks.torch, 4);
		setBlockAndMetadata(world, 1, 11, 1, Blocks.torch, 4);
		for (i1 = -9; i1 <= -6; ++i1) {
			for (k12 = -9; k12 <= -6; ++k12) {
				setBlockAndMetadata(world, i1, 0, k12, pillarBlock, pillarMeta);
			}
		}
		for (j15 = 1; j15 <= 4; ++j15) {
			setBlockAndMetadata(world, -6, j15, -6, woodBeamBlock, woodBeamMeta);
		}
		setBlockAndMetadata(world, -6, 5, -6, plankSlabBlock, plankSlabMeta);
		setBlockAndMetadata(world, -6, 2, -5, Blocks.torch, 3);
		setBlockAndMetadata(world, -5, 2, -6, Blocks.torch, 2);
		for (j15 = 1; j15 <= 3; ++j15) {
			setBlockAndMetadata(world, -9, j15, -6, fenceBlock, fenceMeta);
			setBlockAndMetadata(world, -6, j15, -9, fenceBlock, fenceMeta);
		}
		setBlockAndMetadata(world, -7, 3, -6, fenceBlock, fenceMeta);
		setBlockAndMetadata(world, -6, 3, -7, fenceBlock, fenceMeta);
		for (i1 = -9; i1 <= -7; ++i1) {
			for (k12 = -9; k12 <= -7; ++k12) {
				if (i1 < -8 && k12 < -8) {
					continue;
				}
				setBlockAndMetadata(world, i1, 4, k12, plankBlock, plankMeta);
			}
		}
		for (i1 = -9; i1 <= -7; ++i1) {
			setBlockAndMetadata(world, i1, 4, -6, plankStairBlock, 3);
		}
		for (int k16 = -9; k16 <= -7; ++k16) {
			setBlockAndMetadata(world, -6, 4, k16, plankStairBlock, 0);
		}
		setBlockAndMetadata(world, -8, 1, -10, Blocks.stonebrick, 0);
		setBlockAndMetadata(world, -8, 2, -10, GOTBlocks.alloyForge, 3);
		setBlockAndMetadata(world, -10, 1, -8, Blocks.stonebrick, 0);
		setBlockAndMetadata(world, -10, 2, -8, Blocks.furnace, 4);
		setBlockAndMetadata(world, -7, 1, -6, Blocks.anvil, 1);
		setBlockAndMetadata(world, -6, 1, -7, Blocks.cauldron, 3);
		GOTEntityYiTiBlacksmith blacksmith = new GOTEntityYiTiBlacksmith(world);
		spawnNPCAndSetHome(blacksmith, world, -8, 1, -8, 8);
		for (j1 = 1; j1 <= 4; ++j1) {
			setBlockAndMetadata(world, 6, j1, -6, woodBeamBlock, woodBeamMeta);
		}
		setBlockAndMetadata(world, 6, 5, -6, plankSlabBlock, plankSlabMeta);
		setBlockAndMetadata(world, 6, 2, -5, Blocks.torch, 3);
		setBlockAndMetadata(world, 5, 2, -6, Blocks.torch, 1);
		for (j1 = 1; j1 <= 3; ++j1) {
			setBlockAndMetadata(world, 9, j1, -6, fenceBlock, fenceMeta);
			setBlockAndMetadata(world, 6, j1, -9, fenceBlock, fenceMeta);
		}
		setBlockAndMetadata(world, 7, 3, -6, fenceBlock, fenceMeta);
		setBlockAndMetadata(world, 6, 3, -7, fenceBlock, fenceMeta);
		for (i15 = 7; i15 <= 9; ++i15) {
			for (k1 = -9; k1 <= -7; ++k1) {
				if (i15 > 8 && k1 < -8) {
					continue;
				}
				setBlockAndMetadata(world, i15, 4, k1, plankBlock, plankMeta);
			}
		}
		for (i15 = 7; i15 <= 9; ++i15) {
			setBlockAndMetadata(world, i15, 4, -6, plankStairBlock, 3);
		}
		for (k12 = -9; k12 <= -7; ++k12) {
			setBlockAndMetadata(world, 6, 4, k12, plankStairBlock, 1);
		}
		for (i15 = 7; i15 <= 8; ++i15) {
			placeChest(world, random, i15, 1, -9, 3, GOTChestContents.YI_TI);
		}
		setBlockAndMetadata(world, 9, 1, -8, tableBlock, 0);
		setBlockAndMetadata(world, 9, 1, -7, Blocks.crafting_table, 0);
		setBlockAndMetadata(world, 8, 1, -5, GOTBlocks.commandTable, 0);
		placeWeaponRack(world, -8, 2, -3, 5, new ItemStack(GOTItems.yitiBow));
		placeWeaponRack(world, -8, 2, 3, 5, new ItemStack(GOTItems.yitiBow));
		setBlockAndMetadata(world, -9, 1, -1, plankStairBlock, 6);
		setBlockAndMetadata(world, -9, 1, 0, Blocks.wool, 0);
		setBlockAndMetadata(world, -9, 1, 1, plankStairBlock, 7);
		setBlockAndMetadata(world, -9, 2, -1, Blocks.wool, 0);
		setBlockAndMetadata(world, -9, 2, 0, Blocks.wool, 14);
		setBlockAndMetadata(world, -9, 2, 1, Blocks.wool, 0);
		setBlockAndMetadata(world, -9, 3, -1, plankStairBlock, 2);
		setBlockAndMetadata(world, -9, 3, 0, Blocks.wool, 0);
		setBlockAndMetadata(world, -9, 3, 1, plankStairBlock, 3);
		setBlockAndMetadata(world, -8, 2, 0, Blocks.wooden_button, 2);
		placeWeaponRack(world, 8, 2, -3, 7, new ItemStack(GOTItems.yitiSword));
		placeWeaponRack(world, 8, 2, 3, 7, new ItemStack(GOTItems.yitiSword));
		setBlockAndMetadata(world, 8, 1, 0, fenceBlock, fenceMeta);
		setBlockAndMetadata(world, 8, 2, 0, Blocks.hay_block, 0);
		setBlockAndMetadata(world, 8, 3, 0, Blocks.pumpkin, 3);
		setBlockAndMetadata(world, 8, 2, -1, Blocks.lever, 4);
		setBlockAndMetadata(world, 8, 2, 1, Blocks.lever, 3);
		for (j1 = 0; j1 <= 7; ++j1) {
			setBlockAndMetadata(world, -1, j1, 9, pillarBlock, pillarMeta);
			setBlockAndMetadata(world, 1, j1, 9, pillarBlock, pillarMeta);
		}
		for (j1 = 1; j1 <= 4; ++j1) {
			setBlockAndMetadata(world, 0, j1, 9, Blocks.ladder, 2);
		}
		setAir(world, 0, 5, 9);
		setAir(world, 0, 6, 9);
		setBlockAndMetadata(world, 0, 5, 10, brickStairBlock, 2);
		int[] j3 = {-6, 6};
		k1 = j3.length;
		for (j16 = 0; j16 < k1; ++j16) {
			int i110 = j3[j16];
			for (int l = 0; l <= 4; ++l) {
				int j18 = 1 + l;
				int k15 = 6 + l;
				for (i2 = i110 - 1; i2 <= i110 + 1; ++i2) {
					setBlockAndMetadata(world, i2, j18, k15, brickStairBlock, 2);
					for (int j2 = j18 - 1; j2 >= 1 && !isOpaque(world, i2, j2, k15); --j2) {
						setBlockAndMetadata(world, i2, j2, k15, brickBlock, brickMeta);
						setGrassToDirt(world, i2, j2 - 1, k15);
					}
					if (k15 != 9) {
						continue;
					}
					setAir(world, i2, 5, k15);
					setAir(world, i2, 6, k15);
				}
			}
		}
		for (int i111 = -4; i111 <= 4; ++i111) {
			if (Math.abs(i111) < 2) {
				continue;
			}
			for (k1 = 8; k1 <= 9; ++k1) {
				if (isOpaque(world, i111, 1, k1)) {
					continue;
				}
				int h = 1;
				if (random.nextInt(4) == 0) {
					++h;
				}
				setGrassToDirt(world, i111, 0, k1);
				for (j13 = 1; j13 < 1 + h; ++j13) {
					setBlockAndMetadata(world, i111, j13, k1, Blocks.hay_block, 0);
				}
			}
		}
		setBlockAndMetadata(world, 4, 1, 7, Blocks.cauldron, 3);
		for (int i110 : new int[]{-2, 2}) {
			setBlockAndMetadata(world, i110, 1, 6, fenceBlock, fenceMeta);
			setBlockAndMetadata(world, i110, 2, 6, fenceBlock, fenceMeta);
			GOTEntityHorse horse = new GOTEntityHorse(world);
			spawnNPCAndSetHome(horse, world, i110, 1, 5, 0);
			horse.setHorseType(0);
			horse.saddleMountForWorldGen();
			horse.detachHome();
			leashEntityTo(horse, world, i110, 2, 6);
		}
		GOTEntityRedPriest priest = new GOTEntityRedPriest(world);
		priest.setSpawnRidingHorse(false);
		spawnNPCAndSetHome(priest, world, 0, 1, 0, 12);
		GOTEntityYiTiShogune captain = new GOTEntityYiTiShogune(world);
		captain.setSpawnRidingHorse(false);
		spawnNPCAndSetHome(captain, world, 0, 1, 0, 12);
		int soldiers = 4 + random.nextInt(4);
		for (int l = 0; l < soldiers; ++l) {
			GOTEntityYiTiSoldier soldier = random.nextInt(3) == 0 ? new GOTEntityYiTiSoldierCrossbower(world) : new GOTEntityYiTiSoldier(world);
			if (random.nextInt(3) == 0) {
				soldier = new GOTEntityYiTiSamurai(world);
			}
			soldier.setSpawnRidingHorse(false);
			spawnNPCAndSetHome(soldier, world, 0, 1, 0, 16);
		}
		GOTEntityNPCRespawner respawner = new GOTEntityNPCRespawner(world);
		respawner.setSpawnClass1(GOTEntityYiTiSoldier.class);
		respawner.setSpawnClass2(GOTEntityYiTiSoldierCrossbower.class);
		respawner.setCheckRanges(20, -8, 12, 10);
		respawner.setSpawnRanges(10, 0, 8, 16);
		placeNPCRespawner(respawner, world, 0, 0, 0);
		GOTEntityNPCRespawner respawnerGold = new GOTEntityNPCRespawner(world);
		respawnerGold.setSpawnClass1(GOTEntityYiTiSamurai.class);
		respawnerGold.setCheckRanges(20, -8, 12, 5);
		respawnerGold.setSpawnRanges(10, 0, 8, 16);
		placeNPCRespawner(respawnerGold, world, 0, 0, 0);
		return true;
	}

	@Override
	public void setupRandomBlocks(Random random) {
		super.setupRandomBlocks(random);
		bedBlock = GOTBlocks.strawBed;
	}
}