package got.common.world.structure.essos.yiti;

import com.google.common.math.IntMath;
import got.common.database.GOTChestContents;
import got.common.database.GOTFoods;
import got.common.database.GOTRegistry;
import got.common.entity.essos.yiti.GOTEntityYiTiMan;
import net.minecraft.init.Blocks;
import net.minecraft.init.Items;
import net.minecraft.item.ItemStack;
import net.minecraft.world.World;

import java.util.Random;

public class GOTStructureYiTiLargeTownHouse extends GOTStructureYiTiBaseTown {
	public GOTStructureYiTiLargeTownHouse(boolean flag) {
		super(flag);
	}

	@Override
	public boolean generate(World world, Random random, int i, int j, int k, int rotation) {
		int j1;
		int j12;
		int k1;
		int i1;
		int k122;
		int i122;
		int k13;
		int i13;
		int i2;
		int l;
		int k2;
		int k14;
		int i14;
		setOriginAndRotation(world, i, j, k, rotation, 9);
		setupRandomBlocks(random);
		if (restrictions) {
			int minHeight = 0;
			int maxHeight = 0;
			for (int i15 = -7; i15 <= 7; ++i15) {
				for (k122 = -9; k122 <= 9; ++k122) {
					j1 = getTopBlock(world, i15, k122) - 1;
					if (!isSurface(world, i15, j1, k122)) {
						return false;
					}
					if (j1 < minHeight) {
						minHeight = j1;
					}
					if (j1 > maxHeight) {
						maxHeight = j1;
					}
					if (maxHeight - minHeight <= 8) {
						continue;
					}
					return false;
				}
			}
		}
		for (i1 = -6; i1 <= 6; ++i1) {
			for (k1 = -8; k1 <= 8; ++k1) {
				i2 = Math.abs(i1);
				k2 = Math.abs(k1);
				if (k2 == 8 && i2 % 4 == 2 || i2 == 6 && k2 % 4 == 0) {
					for (j1 = 4; (j1 >= 0 || !isOpaque(world, i1, j1, k1)) && getY(j1) >= 0; --j1) {
						setBlockAndMetadata(world, i1, j1, k1, woodBeamBlock, woodBeamMeta);
						setGrassToDirt(world, i1, j1 - 1, k1);
					}
					continue;
				}
				if (i2 == 6 || k2 == 8) {
					for (j1 = 3; (j1 >= 0 || !isOpaque(world, i1, j1, k1)) && getY(j1) >= 0; --j1) {
						setBlockAndMetadata(world, i1, j1, k1, brickBlock, brickMeta);
						setGrassToDirt(world, i1, j1 - 1, k1);
					}
					if (k2 == 8) {
						setBlockAndMetadata(world, i1, 4, k1, woodBeamBlock, woodBeamMeta | 4);
						continue;
					}
					setBlockAndMetadata(world, i1, 4, k1, woodBeamBlock, woodBeamMeta | 8);
					continue;
				}
				for (j1 = 0; (j1 >= 0 || !isOpaque(world, i1, j1, k1)) && getY(j1) >= 0; --j1) {
					if (IntMath.mod(i1, 2) == 1 && IntMath.mod(k1, 2) == 1) {
						setBlockAndMetadata(world, i1, j1, k1, pillarRedBlock, pillarRedMeta);
					} else {
						setBlockAndMetadata(world, i1, j1, k1, brickRedBlock, brickRedMeta);
					}
					setGrassToDirt(world, i1, j1 - 1, k1);
				}
				for (j1 = 1; j1 <= 14; ++j1) {
					setAir(world, i1, j1, k1);
				}
			}
		}
		for (i1 = -1; i1 <= 1; ++i1) {
			for (k1 = -3; k1 <= -1; ++k1) {
				setBlockAndMetadata(world, i1, 0, k1, brickGoldBlock, brickGoldMeta);
			}
		}
		for (int k1221 : new int[]{-4, 0, 4}) {
			for (i13 = -5; i13 <= 5; ++i13) {
				setBlockAndMetadata(world, i13, 0, k1221, woodBeamBlock, woodBeamMeta | 4);
			}
		}
		for (int i1221 : new int[]{-2, 2}) {
			for (k13 = -7; k13 <= 7; ++k13) {
				setBlockAndMetadata(world, i1221, 0, k13, woodBeamBlock, woodBeamMeta | 8);
			}
		}
		for (int i1221 : new int[]{-4, 4}) {
			setBlockAndMetadata(world, i1221 - 1, 2, -8, brickStairBlock, 4);
			setAir(world, i1221, 2, -8);
			setBlockAndMetadata(world, i1221 + 1, 2, -8, brickStairBlock, 5);
			setBlockAndMetadata(world, i1221, 3, -8, brickStairBlock, 6);
			setBlockAndMetadata(world, i1221 - 1, 2, 8, brickStairBlock, 4);
			setAir(world, i1221, 2, 8);
			setBlockAndMetadata(world, i1221 + 1, 2, 8, brickStairBlock, 5);
			setBlockAndMetadata(world, i1221, 3, 8, brickStairBlock, 7);
		}
		for (int k1221 : new int[]{-6, -2, 2, 6}) {
			setBlockAndMetadata(world, -6, 2, k1221 - 1, brickStairBlock, 7);
			setAir(world, -6, 2, k1221);
			setBlockAndMetadata(world, -6, 2, k1221 + 1, brickStairBlock, 6);
			setBlockAndMetadata(world, -6, 3, k1221, brickStairBlock, 5);
			setBlockAndMetadata(world, 6, 2, k1221 - 1, brickStairBlock, 7);
			setAir(world, 6, 2, k1221);
			setBlockAndMetadata(world, 6, 2, k1221 + 1, brickStairBlock, 6);
			setBlockAndMetadata(world, 6, 3, k1221, brickStairBlock, 4);
		}
		for (int k1221 : new int[]{-9, 9}) {
			setBlockAndMetadata(world, -6, 3, k1221, fenceBlock, fenceMeta);
			setBlockAndMetadata(world, 6, 3, k1221, fenceBlock, fenceMeta);
		}
		for (int i1221 : new int[]{-7, 7}) {
			setBlockAndMetadata(world, i1221, 3, -8, fenceBlock, fenceMeta);
			setBlockAndMetadata(world, i1221, 3, 8, fenceBlock, fenceMeta);
		}
		for (int i1221 : new int[]{-2, 2}) {
			setBlockAndMetadata(world, i1221, 3, -9, Blocks.torch, 4);
			setBlockAndMetadata(world, i1221, 3, 9, Blocks.torch, 3);
		}
		int[] i16 = {-4, 0, 4};
		k1 = i16.length;
		for (i2 = 0; i2 < k1; ++i2) {
			k122 = i16[i2];
			setBlockAndMetadata(world, -7, 3, k122, Blocks.torch, 1);
			setBlockAndMetadata(world, 7, 3, k122, Blocks.torch, 2);
		}
		for (int i17 = -5; i17 <= 5; ++i17) {
			for (k1 = -7; k1 <= 7; ++k1) {
				setBlockAndMetadata(world, i17, 4, k1, plankSlabBlock, plankSlabMeta | 8);
			}
		}
		for (int k1221 : new int[]{-4, 4}) {
			for (i13 = -5; i13 <= 5; ++i13) {
				setBlockAndMetadata(world, i13, 4, k1221, woodBeamBlock, woodBeamMeta | 4);
			}
		}
		for (int i1221 : new int[]{-2, 2}) {
			for (k13 = -7; k13 <= 7; ++k13) {
				if (k13 > -5 && k13 < 5) {
					continue;
				}
				setBlockAndMetadata(world, i1221, 4, k13, woodBeamBlock, woodBeamMeta | 8);
			}
		}
		int[] i17 = {-2, 2};
		k1 = i17.length;
		for (i2 = 0; i2 < k1; ++i2) {
			i122 = i17[i2];
			for (j1 = 1; j1 <= 3; ++j1) {
				setBlockAndMetadata(world, i122, j1, -4, woodBeamBlock, woodBeamMeta);
			}
			for (j1 = 1; j1 <= 4; ++j1) {
				setBlockAndMetadata(world, i122, j1, 0, woodBeamBlock, woodBeamMeta);
			}
		}
		for (int l2 = 0; l2 <= 4; ++l2) {
			int j13 = 1 + l2;
			int k15 = -1 + l2;
			for (i122 = -1; i122 <= 1; ++i122) {
				setAir(world, i122, 4, k15);
				if (l2 <= 3) {
					setBlockAndMetadata(world, i122, j13, k15, plankStairBlock, 2);
				}
				for (int j2 = j13 - 1; j2 >= 1; --j2) {
					setBlockAndMetadata(world, i122, j2, k15, plankBlock, plankMeta);
				}
			}
		}
		for (int k16 = -1; k16 <= 3; ++k16) {
			setBlockAndMetadata(world, -2, 5, k16, fenceBlock, fenceMeta);
			setBlockAndMetadata(world, 2, 5, k16, fenceBlock, fenceMeta);
		}
		for (int i18 = -2; i18 <= 2; ++i18) {
			setBlockAndMetadata(world, i18, 5, -2, fenceBlock, fenceMeta);
		}
		for (int i1221 : new int[]{-2, 2}) {
			for (int k17 : new int[]{0, 4}) {
				setBlockAndMetadata(world, i1221, 5, k17, woodBeamBlock, woodBeamMeta);
				setBlockAndMetadata(world, i1221, 6, k17, plankSlabBlock, plankSlabMeta);
			}
		}
		for (int i19 = -5; i19 <= 5; ++i19) {
			for (k1 = -7; k1 <= 7; ++k1) {
				i2 = Math.abs(i19);
				k2 = Math.abs(k1);
				if (i2 == 5 && (k2 == 0 || k2 == 4 || k2 == 7) || k2 == 7 && i2 == 2) {
					for (j1 = 5; j1 <= 8; ++j1) {
						setBlockAndMetadata(world, i19, j1, k1, woodBeamBlock, woodBeamMeta);
					}
					continue;
				}
				if (i2 != 5 && k2 != 7) {
					continue;
				}
				for (j1 = 5; j1 <= 7; ++j1) {
					setBlockAndMetadata(world, i19, j1, k1, brickBlock, brickMeta);
				}
				if (k2 == 7) {
					setBlockAndMetadata(world, i19, 8, k1, woodBeamBlock, woodBeamMeta | 4);
					continue;
				}
				setBlockAndMetadata(world, i19, 8, k1, woodBeamBlock, woodBeamMeta | 8);
			}
		}
		setBlockAndMetadata(world, 0, 6, -7, GOTRegistry.reedBars, 0);
		for (int i1221 : new int[]{-5, 5}) {
			setBlockAndMetadata(world, i1221, 6, -2, GOTRegistry.reedBars, 0);
			setBlockAndMetadata(world, i1221, 6, 2, GOTRegistry.reedBars, 0);
		}
		for (int k1221 : new int[]{-8, 8}) {
			setBlockAndMetadata(world, -5, 7, k1221, fenceBlock, fenceMeta);
			setBlockAndMetadata(world, 5, 7, k1221, fenceBlock, fenceMeta);
		}
		for (int i1221 : new int[]{-6, 6}) {
			setBlockAndMetadata(world, i1221, 7, -7, fenceBlock, fenceMeta);
			setBlockAndMetadata(world, i1221, 7, 7, fenceBlock, fenceMeta);
		}
		for (int i1221 : new int[]{-2, 2}) {
			setBlockAndMetadata(world, i1221, 7, -8, Blocks.torch, 4);
			setBlockAndMetadata(world, i1221, 7, 8, Blocks.torch, 3);
		}
		for (int k1221 : new int[]{-4, 0, 4}) {
			setBlockAndMetadata(world, -6, 7, k1221, Blocks.torch, 1);
			setBlockAndMetadata(world, 6, 7, k1221, Blocks.torch, 2);
		}
		for (int i110 = -6; i110 <= 6; ++i110) {
			setBlockAndMetadata(world, i110, 5, -8, roofStairBlock, 2);
			setBlockAndMetadata(world, i110, 5, 8, roofStairBlock, 3);
		}
		for (int k18 = -7; k18 <= 7; ++k18) {
			setBlockAndMetadata(world, -6, 5, k18, roofStairBlock, 1);
			setBlockAndMetadata(world, 6, 5, k18, roofStairBlock, 0);
		}
		for (int k1221 : new int[]{-9, 9}) {
			setBlockAndMetadata(world, -7, 5, k1221, roofSlabBlock, roofSlabMeta);
			setBlockAndMetadata(world, -6, 4, k1221, roofStairBlock, 5);
			setBlockAndMetadata(world, -5, 4, k1221, roofStairBlock, 4);
			setBlockAndMetadata(world, -4, 5, k1221, roofSlabBlock, roofSlabMeta);
			setBlockAndMetadata(world, -3, 4, k1221, roofStairBlock, 5);
			setBlockAndMetadata(world, -2, 4, k1221, roofStairBlock, k1221 > 0 ? 3 : 2);
			setBlockAndMetadata(world, -1, 4, k1221, roofStairBlock, 4);
			setBlockAndMetadata(world, 0, 5, k1221, roofSlabBlock, roofSlabMeta);
			setBlockAndMetadata(world, 1, 4, k1221, roofStairBlock, 5);
			setBlockAndMetadata(world, 2, 4, k1221, roofStairBlock, k1221 > 0 ? 3 : 2);
			setBlockAndMetadata(world, 3, 4, k1221, roofStairBlock, 4);
			setBlockAndMetadata(world, 4, 5, k1221, roofSlabBlock, roofSlabMeta);
			setBlockAndMetadata(world, 5, 4, k1221, roofStairBlock, 5);
			setBlockAndMetadata(world, 6, 4, k1221, roofStairBlock, 4);
			setBlockAndMetadata(world, 7, 5, k1221, roofSlabBlock, roofSlabMeta);
		}
		for (int i1221 : new int[]{-7, 7}) {
			for (int k17 : new int[]{-4, 0, 4}) {
				setBlockAndMetadata(world, i1221, 4, k17 - 1, roofStairBlock, 6);
				setBlockAndMetadata(world, i1221, 4, k17, roofStairBlock, i1221 > 0 ? 0 : 1);
				setBlockAndMetadata(world, i1221, 4, k17 + 1, roofStairBlock, 7);
			}
			for (int k17 : new int[]{-6, -2, 2, 6}) {
				setBlockAndMetadata(world, i1221, 5, k17, roofSlabBlock, roofSlabMeta);
			}
			setBlockAndMetadata(world, i1221, 4, -8, roofStairBlock, 6);
			setBlockAndMetadata(world, i1221, 4, -7, roofStairBlock, 7);
			setBlockAndMetadata(world, i1221, 4, 7, roofStairBlock, 6);
			setBlockAndMetadata(world, i1221, 4, 8, roofStairBlock, 7);
		}
		for (int k1221 : new int[]{-8, 8}) {
			setBlockAndMetadata(world, -6, 9, k1221, roofSlabBlock, roofSlabMeta);
			setBlockAndMetadata(world, -5, 8, k1221, roofStairBlock, 5);
			setBlockAndMetadata(world, -4, 8, k1221, roofStairBlock, k1221 > 0 ? 3 : 2);
			setBlockAndMetadata(world, -3, 8, k1221, roofStairBlock, 4);
			setBlockAndMetadata(world, -2, 8, k1221, roofStairBlock, k1221 > 0 ? 3 : 2);
			setBlockAndMetadata(world, -1, 8, k1221, roofStairBlock, 4);
			setBlockAndMetadata(world, 0, 9, k1221, roofSlabBlock, roofSlabMeta);
			setBlockAndMetadata(world, 1, 8, k1221, roofStairBlock, 5);
			setBlockAndMetadata(world, 2, 8, k1221, roofStairBlock, k1221 > 0 ? 3 : 2);
			setBlockAndMetadata(world, 3, 8, k1221, roofStairBlock, 5);
			setBlockAndMetadata(world, 4, 8, k1221, roofStairBlock, k1221 > 0 ? 3 : 2);
			setBlockAndMetadata(world, 5, 8, k1221, roofStairBlock, 4);
			setBlockAndMetadata(world, 6, 9, k1221, roofSlabBlock, roofSlabMeta);
		}
		int[] k18 = {-6, 6};
		k1 = k18.length;
		for (i2 = 0; i2 < k1; ++i2) {
			i122 = k18[i2];
			setBlockAndMetadata(world, i122, 8, -7, roofStairBlock, 6);
			for (k13 = -6; k13 <= -4; ++k13) {
				setBlockAndMetadata(world, i122, 8, k13, roofStairBlock, i122 > 0 ? 0 : 1);
			}
			setBlockAndMetadata(world, i122, 8, -3, roofStairBlock, 7);
			setBlockAndMetadata(world, i122, 9, -2, roofSlabBlock, roofSlabMeta);
			setBlockAndMetadata(world, i122, 8, -1, roofStairBlock, 6);
			setBlockAndMetadata(world, i122, 9, 0, roofStairBlock, i122 > 0 ? 0 : 1);
			setBlockAndMetadata(world, i122, 8, 1, roofStairBlock, 7);
			setBlockAndMetadata(world, i122, 9, 2, roofSlabBlock, roofSlabMeta);
			setBlockAndMetadata(world, i122, 8, 3, roofStairBlock, 6);
			for (k13 = 4; k13 <= 6; ++k13) {
				setBlockAndMetadata(world, i122, 8, k13, roofStairBlock, i122 > 0 ? 0 : 1);
			}
			setBlockAndMetadata(world, i122, 8, 7, roofStairBlock, 7);
		}
		for (int k19 = -7; k19 <= 7; ++k19) {
			for (l = 0; l <= 4; ++l) {
				j12 = 9 + l;
				setBlockAndMetadata(world, -5 + l, j12, k19, roofStairBlock, 1);
				setBlockAndMetadata(world, 5 - l, j12, k19, roofStairBlock, 0);
				if (l <= 0) {
					continue;
				}
				setBlockAndMetadata(world, -5 + l, j12 - 1, k19, roofStairBlock, 4);
				setBlockAndMetadata(world, 5 - l, j12 - 1, k19, roofStairBlock, 5);
			}
			setBlockAndMetadata(world, 0, 13, k19, roofBlock, roofMeta);
			setBlockAndMetadata(world, 0, 14, k19, roofSlabBlock, roofSlabMeta);
		}
		setBlockAndMetadata(world, 0, 13, -8, roofStairBlock, 6);
		setBlockAndMetadata(world, 0, 14, -8, roofStairBlock, 3);
		setBlockAndMetadata(world, 0, 13, 8, roofStairBlock, 7);
		setBlockAndMetadata(world, 0, 14, 8, roofStairBlock, 2);
		for (int k1221 : new int[]{-7, 7}) {
			for (int i111 : new int[]{-2, 2}) {
				for (int j14 = 5; j14 <= 11; ++j14) {
					setBlockAndMetadata(world, i111, j14, k1221, woodBeamBlock, woodBeamMeta);
				}
			}
		}
		for (int i112 = -4; i112 <= 4; ++i112) {
			setBlockAndMetadata(world, i112, 8, -6, plankStairBlock, 7);
			setBlockAndMetadata(world, i112, 8, 6, plankStairBlock, 6);
		}
		for (int k1221 : new int[]{-6, 6}) {
			for (int l3 = 0; l3 <= 3; ++l3) {
				int j15 = 9 + l3;
				for (int i113 = -4 + l3; i113 <= 4 - l3; ++i113) {
					setBlockAndMetadata(world, i113, j15, k1221, plankBlock, plankMeta);
				}
			}
		}
		for (int k1221 : new int[]{-4, 4}) {
			for (i13 = -4; i13 <= 4; ++i13) {
				setBlockAndMetadata(world, i13, 8, k1221, woodBeamBlock, woodBeamMeta | 4);
			}
		}
		int[] i112 = {-2, 2};
		l = i112.length;
		for (j12 = 0; j12 < l; ++j12) {
			i122 = i112[j12];
			for (k13 = -6; k13 <= 6; ++k13) {
				setBlockAndMetadata(world, i122, 8, k13, woodBeamBlock, woodBeamMeta | 8);
			}
		}
		setBlockAndMetadata(world, 0, 0, -8, woodBeamBlock, woodBeamMeta | 4);
		setBlockAndMetadata(world, 0, 1, -8, doorBlock, 1);
		setBlockAndMetadata(world, 0, 2, -8, doorBlock, 8);
		setBlockAndMetadata(world, -2, 3, -5, Blocks.torch, 4);
		setBlockAndMetadata(world, 2, 3, -5, Blocks.torch, 4);
		spawnItemFrame(world, -2, 2, -4, 1, getFramedItem(random));
		spawnItemFrame(world, 2, 2, -4, 3, getFramedItem(random));
		setBlockAndMetadata(world, -3, 1, -6, plankStairBlock, 1);
		setBlockAndMetadata(world, 3, 1, -6, plankStairBlock, 0);
		for (k14 = -7; k14 <= -5; ++k14) {
			setBlockAndMetadata(world, -5, 1, k14, plankStairBlock, 4);
			if (random.nextBoolean()) {
				placePlate(world, random, -5, 2, k14, plateBlock, GOTFoods.YITI);
			} else {
				placeMug(world, random, -5, 2, k14, 3, GOTFoods.YITI_DRINK);
			}
			setBlockAndMetadata(world, 5, 1, k14, plankStairBlock, 5);
			if (random.nextBoolean()) {
				placePlate(world, random, 5, 2, k14, plateBlock, GOTFoods.YITI);
				continue;
			}
			placeMug(world, random, 5, 2, k14, 1, GOTFoods.YITI_DRINK);
		}
		spawnItemFrame(world, -6, 2, 0, 1, getFramedItem(random));
		spawnItemFrame(world, 6, 2, 0, 3, getFramedItem(random));
		setBlockAndMetadata(world, -2, 1, 1, Blocks.chest, 5);
		setBlockAndMetadata(world, -2, 1, 2, Blocks.chest, 5);
		setBlockAndMetadata(world, 2, 1, 1, Blocks.chest, 4);
		setBlockAndMetadata(world, 2, 1, 2, Blocks.chest, 4);
		setBlockAndMetadata(world, -2, 1, 3, plankStairBlock, 5);
		placeBarrel(world, random, -2, 2, 3, 5, GOTFoods.YITI_DRINK);
		setBlockAndMetadata(world, 2, 1, 3, plankStairBlock, 4);
		placeBarrel(world, random, 2, 2, 3, 4, GOTFoods.YITI_DRINK);
		setBlockAndMetadata(world, -2, 3, 4, GOTRegistry.chandelier, 3);
		setBlockAndMetadata(world, 2, 3, 4, GOTRegistry.chandelier, 3);
		setBlockAndMetadata(world, 0, 1, 3, tableBlock, 0);
		setAir(world, 0, 2, 3);
		setBlockAndMetadata(world, 0, 3, 3, plankStairBlock, 7);
		for (i14 = -1; i14 <= 1; ++i14) {
			for (k1 = 5; k1 <= 7; ++k1) {
				setBlockAndMetadata(world, i14, 0, k1, brickBlock, brickMeta);
			}
			for (k1 = 7; k1 <= 8; ++k1) {
				for (j12 = 1; j12 <= 4; ++j12) {
					setBlockAndMetadata(world, i14, j12, k1, brickBlock, brickMeta);
				}
			}
			k1 = 9;
			for (j12 = 4; (j12 >= 0 || !isOpaque(world, i14, j12, k1)) && getY(j12) >= 0; --j12) {
				setBlockAndMetadata(world, i14, j12, k1, brickBlock, brickMeta);
				setGrassToDirt(world, i14, j12 - 1, k1);
			}
			setBlockAndMetadata(world, i14, 5, 9, brickStairBlock, 3);
			setBlockAndMetadata(world, i14, 4, 8, brickBlock, brickMeta);
			setBlockAndMetadata(world, i14, 5, 8, brickBlock, brickMeta);
			setBlockAndMetadata(world, i14, 6, 8, brickStairBlock, 3);
		}
		setBlockAndMetadata(world, -1, 1, 7, brickStairBlock, 1);
		setBlockAndMetadata(world, -1, 2, 7, brickStairBlock, 5);
		setBlockAndMetadata(world, -1, 3, 7, brickStairBlock, 5);
		setBlockAndMetadata(world, 1, 1, 7, brickStairBlock, 0);
		setBlockAndMetadata(world, 1, 2, 7, brickStairBlock, 4);
		setBlockAndMetadata(world, 1, 3, 7, brickStairBlock, 4);
		setBlockAndMetadata(world, 0, 0, 7, GOTRegistry.hearth, 0);
		setBlockAndMetadata(world, 0, 1, 7, barsBlock, 0);
		setBlockAndMetadata(world, 0, 2, 7, Blocks.furnace, 2);
		setBlockAndMetadata(world, 0, 0, 8, GOTRegistry.hearth, 0);
		setBlockAndMetadata(world, 0, 1, 8, Blocks.fire, 0);
		setAir(world, 0, 2, 8);
		setBlockAndMetadata(world, -5, 1, 5, plankStairBlock, 4);
		setBlockAndMetadata(world, -5, 1, 6, Blocks.crafting_table, 0);
		setBlockAndMetadata(world, -5, 1, 7, plankBlock, plankMeta);
		setBlockAndMetadata(world, -4, 1, 7, Blocks.cauldron, 3);
		setBlockAndMetadata(world, -3, 1, 7, plankStairBlock, 6);
		setBlockAndMetadata(world, 5, 1, 5, plankStairBlock, 5);
		setBlockAndMetadata(world, 5, 1, 6, plankStairBlock, 5);
		setBlockAndMetadata(world, 5, 1, 7, plankStairBlock, 5);
		setBlockAndMetadata(world, 4, 1, 7, plankStairBlock, 6);
		setBlockAndMetadata(world, 3, 1, 7, plankStairBlock, 6);
		for (i14 = 3; i14 <= 5; ++i14) {
			if (random.nextBoolean()) {
				placePlate(world, random, i14, 2, 7, plateBlock, GOTFoods.YITI);
				continue;
			}
			placeMug(world, random, i14, 2, 7, 0, GOTFoods.YITI_DRINK);
		}
		for (k14 = 5; k14 <= 6; ++k14) {
			if (random.nextBoolean()) {
				placePlate(world, random, 5, 2, k14, plateBlock, GOTFoods.YITI);
				continue;
			}
			placeMug(world, random, 5, 2, k14, 1, GOTFoods.YITI_DRINK);
		}
		placeWallBanner(world, 0, 7, 7, bannerType, 2);
		setBlockAndMetadata(world, -2, 7, 4, GOTRegistry.chandelier, 3);
		setBlockAndMetadata(world, 2, 7, 4, GOTRegistry.chandelier, 3);
		placeArmorStand(world, -4, 5, 6, 0, null);
		placeArmorStand(world, 4, 5, 6, 0, null);
		setBlockAndMetadata(world, -2, 7, -4, GOTRegistry.chandelier, 3);
		setBlockAndMetadata(world, 2, 7, -4, GOTRegistry.chandelier, 3);
		for (int i1221 : new int[]{-4, 0, 4}) {
			setBlockAndMetadata(world, i1221, 5, -5, bedBlock, 2);
			setBlockAndMetadata(world, i1221, 5, -6, bedBlock, 10);
		}
		for (int i1221 : new int[]{-2, 2}) {
			placeChest(world, random, i1221, 5, -6, 3, GOTChestContents.YI_TI);
		}
		for (int i1221 : new int[]{-3, -1, 1, 3}) {
			setBlockAndMetadata(world, i1221, 5, -6, plankStairBlock, 7);
			if (random.nextBoolean()) {
				placePlate(world, random, i1221, 6, -6, plateBlock, GOTFoods.YITI);
				continue;
			}
			placeMug(world, random, i1221, 6, -6, 2, GOTFoods.YITI_DRINK);
		}
		placeWeaponRack(world, 0, 7, -6, 4, getWeaponItem(random));
		if (random.nextBoolean()) {
			spawnItemFrame(world, -2, 7, -7, 0, new ItemStack(Items.clock));
		} else {
			spawnItemFrame(world, 2, 7, -7, 0, new ItemStack(Items.clock));
		}
		GOTEntityYiTiMan male = new GOTEntityYiTiMan(world);
		male.familyInfo.setMale(true);
		male.setCurrentItemOrArmor(4, new ItemStack(GOTRegistry.goldRing));
		spawnNPCAndSetHome(male, world, 0, 5, 3, 16);
		GOTEntityYiTiMan female = new GOTEntityYiTiMan(world);
		female.familyInfo.setMale(false);
		female.setCurrentItemOrArmor(4, new ItemStack(GOTRegistry.goldRing));
		spawnNPCAndSetHome(female, world, 0, 5, 3, 16);
		GOTEntityYiTiMan child = new GOTEntityYiTiMan(world);
		child.familyInfo.setMale(random.nextBoolean());
		child.familyInfo.setChild();
		spawnNPCAndSetHome(child, world, 0, 5, 3, 16);
		return true;
	}
}
